Workbook

Sheet 0_Sampling
A1: Sampling
A3: Sampling date | B3: Sample ID | C3: Subsite | D3: Working ID
A4: 45486 | B4: AP1_0-20 | C4: Palsa | D4: P1
A5: 45486 | B5: AP1_20-40 | C5: Palsa | D5: P2
A6: 45486 | B6: AP1_50-69 | C6: Palsa | D6: P3
A7: 45486 | B7: AP1_80-100 | C7: Palsa | D7: P4
A8: 45486 | B8: AP1_100-120 | C8: Palsa | D8: P5
A9: 45486 | B9: AP2_0-20 | C9: Palsa | D9: P16
A10: 45486 | B10: AP2_20-40 | C10: Palsa | D10: P7
A11: 45486 | B11: AP2_50-69 | C11: Palsa | D11: P8
A12: 45486 | B12: AP2_80-100 | C12: Palsa | D12: P9
A13: 45486 | B13: AP2_100-120 | C13: Palsa | D13: P10
A14: 45486 | B14: AP3_0-20 | C14: Palsa | D14: P11
A15: 45486 | B15: AP3_20-40 | C15: Palsa | D15: P12
... A43: 45488 | B43: AT5_150-170 | C43: Thermokarst | D43: P40

Sheet 1_Water content
A1: Water content | L1: Drying of samples for analyses
A2: 45603 | C2: Samples P1, P2, P11, P12 see table 2_water holding capacity | L2: 45608 | O2: Samples P1, P2, P11, P12 see table 2_water holding capacity
A3: Measure 5-10 g sample, dry at 105 °C | L3: Weighing of total samples into aluminum bowls and drying
A4: Start of drying: 7.11., 14:30h
A5: End of drying: 8.11., 11:00h
A8: Sample ID | B8: Working ID | C8: Weight bowl empty [g] | D8: Fresh weight + bowl [g] | E8: Dry weight + bowl [g] | F8: Dry weight [%] | G8: Dry weight [g] | H8: Absolute mass water [g] | I8: gravimetric water content [g/g] | J8: water content [%] | K8: WHC [g/g] | L8: Weight bowl [g] | M8: Total weight sample + bowl [g] | N8: Total weight sample [g] | O8: Total dry weight [g] | P8: Water content at 150% [g] | Q8: Weight of sample at 150% water content [g] | R8: Weight of sample + bowl at 150% water content [g] | S8: Weight of sample + bowl after drying [g] | T8: Weight of sample after drying [g] | U8: Water content [g/g] | V8: Attention: water content of aerobic samples lower after pre-incubation (see table 3)
A9: AP1_0-20 | B9: P1 | I9: 3.5363128
A10: AP1_20-40 | B10: P2 | I10: 5.5964912
A11: AP1_50-69 | B11: P3 | C11: 1.172 | D11: 8.981 | E11: 2.804 | F11: =E11/D11 -> 0.31221468 | G11: =E11-C11 -> 1.632 | H11: =D11-E11 -> 6.177 | I11: =H11/G11 -> 3.7849265 | J11: =H11/(D11-C11) -> 0.79101037 | K11: =H11/G11 -> 3.7849265 | L11: 10.7 | M11: 139.4 | N11: =M11-L11 -> 128.7 | O11: =N11/(1+K11) -> 26.896965 | P11: =O11*1.5 -> 40.345448 | Q11: =O11+P11 -> 67.242413 | R11: =Q11+L11 -> 77.942413 | S11: 78.8 | T11: =S11-L11 -> 68.1 | U11: =(T11-O11)/O11 -> 1.5318842
A12: AP1_80-100 | B12: P4 | C12: 1.177 | D12: 9.121 | E12: 2.374 | F12: =E12/D12 -> 0.26027848 | G12: =E12-C12 -> 1.197 | H12: =D12-E12 -> 6.747 | I12: =H12/(E12-C12) -> 5.6365915 | J12: =H12/(D12-C12) -> 0.84932024 | K12: =H12/G12 -> 5.6365915 | L12: 12.1 | M12: 175.2 | N12: =M12-L12 -> 163.1 | O12: =N12/(1+K12) -> 24.575869 | P12: =O12*1.5 -> 36.863803 | Q12: =O12+P12 -> 61.439671 | R12: =Q12+L12 -> 73.539671 | S12: 75.2 | T12: =S12-L12 -> 63.1 | U12: =(T12-O12)/O12 -> 1.5675593
A13: AP1_100-120 | B13: P5 | C13: 1.175 | D13: 7.422 | E13: 2.172 | F13: =E13/D13 -> 0.29264349 | G13: =E13-C13 -> 0.997 | H13: =D13-E13 -> 5.25 | I13: =H13/(E13-C13) -> 5.2657974 | J13: =H13/(D13-C13) -> 0.84040339 | K13: =H13/G13 -> 5.2657974 | L13: 12 | M13: 165.9 | N13: =M13-L13 -> 153.9 | O13: =N13/(1+K13) -> 24.561918 | P13: =O13*1.5 -> 36.842877 | Q13: =O13+P13 -> 61.404794 | R13: =Q13+L13 -> 73.404794 | S13: 73.7 | T13: =S13-L13 -> 61.7 | U13: =(T13-O13)/O13 -> 1.5120188
A14: AP2_0-20 | B14: P16 | C14: 1.182 | D14: 8.048 | E14: 3.09 | F14: =E14/D14 -> 0.38394632 | G14: =E14-C14 -> 1.908 | H14: =D14-E14 -> 4.958 | I14: =H14/(E14-C14) -> 2.5985325 | J14: =H14/(D14-C14) -> 0.72210894 | K14: =H14/G14 -> 2.5985325 | L14: 38.9 | M14: 342.6 | N14: =M14-L14 -> 303.7 | O14: =N14/(1+K14) -> 84.395514 | P14: =O14*1.5 -> 126.59327 | Q14: =O14+P14 -> 210.98879 | R14: =Q14+L14 -> 249.88879 | S14: 250.7 | T14: =S14-L14 -> 211.8 | U14: =(T14-O14)/O14 -> 1.5096121
A15: AP2_20-40 | B15: P7 | C15: 1.188 | D15: 8.838 | E15: 3.46 | F15: =E15/D15 -> 0.39149129 | G15: =E15-C15 -> 2.272 | H15: =D15-E15 -> 5.378 | I15: =H15/(E15-C15) -> 2.3670775 | J15: =H15/(D15-C15) -> 0.70300654 | K15: =H15/G15 -> 2.3670775 | L15: 11.4 | M15: 278.2 | N15: =M15-L15 -> 266.8 | O15: =N15/(1+K15) -> 79.237856 | P15: =O15*1.5 -> 118.85678 | Q15: =O15+P15 -> 198.09464 | R15: =Q15+L15 -> 209.49464 | S15: 209.6 | T15: =S15-L15 -> 198.2 | U15: =(T15-O15)/O15 -> 1.5013297
A16: AP2_50-69 | B16: P8 | C16: 1.171 | D16: 7.766 | E16: 2.082 | F16: =E16/D16 -> 0.26809168 | G16: =E16-C16 -> 0.911 | H16: =D16-E16 -> 5.684 | I16: =H16/(E16-C16) -> 6.2392975 | J16: =H16/(D16-C16) -> 0.86186505 | K16: =H16/G16 -> 6.2392975 | L16: 11.9 | M16: 156.7 | N16: =M16-L16 -> 144.8 | O16: =N16/(1+K16) -> 20.001941 | P16: =O16*1.5 -> 30.002911 | Q16: =O16+P16 -> 50.004852 | R16: =Q16+L16 -> 61.904852 | S16: 63.3 | T16: =S16-L16 -> 51.4 | U16: =(T16-O16)/O16 -> 1.5697506
A17: AP2_80-100 | B17: P9 | C17: 1.175 | D17: 8.587 | E17: 1.979 | F17: =E17/D17 -> 0.23046466 | G17: =E17-C17 -> 0.804 | H17: =D17-E17 -> 6.608 | I17: =H17/(E17-C17) -> 8.2189055 | J17: =H17/(D17-C17) -> 0.89152725 | K17: =H17/G17 -> 8.2189055 | L17: 12.4 | M17: 182.8 | N17: =M17-L17 -> 170.4 | O17: =N17/(1+K17) -> 18.483756 | P17: =O17*1.5 -> 27.725634 | Q17: =O17+P17 -> 46.20939 | R17: =Q17+L17 -> 58.60939 | S17: 59.2 | T17: =S17-L17 -> 46.8 | U17: =(T17-O17)/O17 -> 1.5319529
A18: AP2_100-120 | B18: P10 | C18: 1.179 | D18: 8.995 | E18: 2.049 | F18: =E18/D18 -> 0.22779322 | G18: =E18-C18 -> 0.87 | H18: =D18-E18 -> 6.946 | I18: =H18/(E18-C18) -> 7.983908 | J18: =H18/(D18-C18) -> 0.88868987 | K18: =H18/G18 -> 7.983908 | L18: 12.8 | M18: 167.4 | N18: =M18-L18 -> 154.6 | O18: =N18/(1+K18) -> 17.208547 | P18: =O18*1.5 -> 25.81282 | Q18: =O18+P18 -> 43.021366 | R18: =Q18+L18 -> 55.821366 | S18: 55.8 | T18: =S18-L18 -> 43 | U18: =(T18-O18)/O18 -> 1.4987584
A19: AP3_0-20 | B19: P11 | I19: 3.0467836 | N19: =M19-L19 -> 0 | O19: =N19/(1+K19) -> 0 | R19: =Q19+L19 -> 0
A20: AP3_20-40 | B20: P12 | I20: 5.7810945 | N20: =M20-L20 -> 0 | O20: =N20/(1+K20) -> 0 | R20: =Q20+L20 -> 0
A21: AP3_50-69 | B21: P13 | C21: 1.177 | D21: 7.338 | E21: 2.187 | F21: =E21/D21 -> 0.29803761 | G21: =E21-C21 -> 1.01 | H21: =D21-E21 -> 5.151 | I21: =H21/(E21-C21) -> 5.1 | J21: =H21/(D21-C21) -> 0.83606557 | K21: =H21/G21 -> 5.1 | L21: 12.3 | M21: 132.1 | N21: =M21-L21 -> 119.8 | O21: =N21/(1+K21) -> 19.639344 | P21: =O21*1.5 -> 29.459016 | Q21: =O21+P21 -> 49.098361 | R21: =Q21+L21 -> 61.398361 | S21: 61.9 | T21: =S21-L21 -> 49.6 | U21: =(T21-O21)/O21 -> 1.5255426
A22: AP3_80-100 | B22: P14 | C22: 1.184 | D22: 7.598 | E22: 2.227 | F22: =E22/D22 -> 0.29310345 | G22: =E22-C22 -> 1.043 | H22: =D22-E22 -> 5.371 | I22: =H22/(E22-C22) -> 5.1495686 | J22: =H22/(D22-C22) -> 0.83738697 | K22: =H22/G22 -> 5.1495686 | L22: 12 | M22: 184 | N22: =M22-L22 -> 172 | O22: =N22/(1+K22) -> 27.969442 | P22: =O22*1.5 -> 41.954163 | Q22: =O22+P22 -> 69.923605 | R22: =Q22+L22 -> 81.923605 | S22: =86-(80.701-76.5) -> 81.799 | T22: =S22-L22 -> 69.799 | U22: =(T22-O22)/O22 -> 1.495545
A23: AP3_100-119 | B23: P15 | C23: 1.168 | D23: 7.611 | E23: 2.019 | F23: =E23/D23 -> 0.26527395 | G23: =E23-C23 -> 0.851 | H23: =D23-E23 -> 5.592 | I23: =H23/(E23-C23) -> 6.5710928 | J23: =H23/(D23-C23) -> 0.86791867 | K23: =H23/G23 -> 6.5710928 | L23: 12.1 | M23: 185.4 | N23: =M23-L23 -> 173.3 | O23: =N23/(1+K23) -> 22.889694 | P23: =O23*1.5 -> 34.334541 | Q23: =O23+P23 -> 57.224236 | R23: =Q23+L23 -> 69.324236 | S23: =73-(68.294-65.2) -> 69.906 | T23: =S23-L23 -> 57.806 | U23: =(T23-O23)/O23 -> 1.525416
A24: AP4_0-20 | B24: P6 | C24: 1.148 | D24: 7.981 | E24: 3.144 | F24: =E24/D24 -> 0.3939356 | G24: =E24-C24 -> 1.996 | H24: =D24-E24 -> 4.837 | I24: =H24/(E24-C24) -> 2.4233467 | J24: =H24/(D24-C24) -> 0.70788819 | K24: =H24/G24 -> 2.4233467 | L24: 38 | M24: 255.8 | N24: =M24-L24 -> 217.8 | O24: =N24/(1+K24) -> 63.621952 | P24: =O24*1.5 -> 95.432928 | Q24: =O24+P24 -> 159.05488 | R24: =Q24+L24 -> 197.05488 | S24: 197.2 | T24: =S24-L24 -> 159.2 | U24: =(T24-O24)/O24 -> 1.502281
A25: AP4_20-40 | B25: P17 | C25: 1.17 | D25: 8.391 | E25: 2.952 | F25: =E25/D25 -> 0.35180551 | G25: =E25-C25 -> 1.782 | H25: =D25-E25 -> 5.439 | I25: =H25/(E25-C25) -> 3.0521886 | J25: =H25/(D25-C25) -> 0.75321978 | K25: =H25/G25 -> 3.0521886 | L25: 38.8 | M25: 403.9 | N25: =M25-L25 -> 365.1 | O25: =N25/(1+K25) -> 90.09946 | P25: =O25*1.5 -> 135.14919 | Q25: =O25+P25 -> 225.24865 | R25: =Q25+L25 -> 264.04865 | S25: 266.2 | T25: =S25-L25 -> 227.4 | U25: =(T25-O25)/O25 -> 1.5238775
A26: AP4_50-70 | B26: P18 | C26: 1.107 | D26: 6.58 | E26: 2.118 | F26: =E26/D26 -> 0.3218845 | G26: =E26-C26 -> 1.011 | H26: =D26-E26 -> 4.462 | I26: =H26/(E26-C26) -> 4.413452 | J26: =H26/(D26-C26) -> 0.81527499 | K26: =H26/G26 -> 4.413452 | L26: 11.9 | M26: 94.1 | N26: =M26-L26 -> 82.2 | O26: =N26/(1+K26) -> 15.184396 | P26: =O26*1.5 -> 22.776594 | Q26: =O26+P26 -> 37.96099 | R26: =Q26+L26 -> 49.86099 | S26: =52.1-(45.791-44.2) -> 50.509 | T26: =S26-L26 -> 38.609 | U26: =(T26-O26)/O26 -> 1.542676
A27: AP4_80-99 | B27: P19 | C27: 1.189 | D27: 8.529 | E27: 1.87 | F27: =E27/D27 -> 0.21925196 | G27: =E27-C27 -> 0.681 | H27: =D27-E27 -> 6.659 | I27: =H27/(E27-C27) -> 9.7782673 | J27: =H27/(D27-C27) -> 0.90722071 | K27: =H27/G27 -> 9.7782673 | L27: 12 | M27: 155.1 | N27: =M27-L27 -> 143.1 | O27: =N27/(1+K27) -> 13.276717 | P27: =O27*1.5 -> 19.915075 | Q27: =O27+P27 -> 33.191792 | R27: =Q27+L27 -> 45.191792 | S27: =47-(41.42-40.3) -> 45.88 | T27: =S27-L27 -> 33.88 | U27: =(T27-O27)/O27 -> 1.5518357
A28: AP4_99-120 | B28: P20 | C28: 1.167 | D28: 7.742 | E28: 1.665 | F28: =E28/D28 -> 0.21506071 | G28: =E28-C28 -> 0.498 | H28: =D28-E28 -> 6.077 | I28: =H28/(E28-C28) -> 12.202811 | J28: =H28/(D28-C28) -> 0.92425856 | K28: =H28/G28 -> 12.202811 | L28: 12.1 | M28: 174.7 | N28: =M28-L28 -> 162.6 | O28: =N28/(1+K28) -> 12.315559 | P28: =O28*1.5 -> 18.473338 | Q28: =O28+P28 -> 30.788897 | R28: =Q28+L28 -> 42.888897 | S28: 43.7 | T28: =S28-L28 -> 31.6 | U28: =(T28-O28)/O28 -> 1.56586
A29: AT1_0-40 | B29: P21 | C29: 1.178 | D29: 8.525 | E29: 1.511 | F29: =E29/D29 -> 0.1772434 | G29: =E29-C29 -> 0.333 | H29: =D29-E29 -> 7.014 | I29: =H29/(E29-C29) -> 21.063063 | J29: =H29/(D29-C29) -> 0.95467538 | K29: =H29/G29 -> 21.063063 | L29: 38.5 | M29: 683.7 | N29: =M29-L29 -> 645.2 | O29: =N29/(1+K29) -> 29.243446 | P29: =O29*2.5 -> 73.108616 | Q29: =O29+P29 -> 102.35206 | R29: =Q29+L29 -> 140.85206 | S29: 142 | T29: =S29-L29 -> 103.5 | U29: =(T29-O29)/O29 -> 2.5392545
A30: AT1_63-83 | B30: P22 | C30: 1.176 | D30: 8.225 | E30: 2.327 | F30: =E30/D30 -> 0.28291793 | G30: =E30-C30 -> 1.151 | H30: =D30-E30 -> 5.898 | I30: =H30/(E30-C30) -> 5.1242398 | J30: =H30/(D30-C30) -> 0.83671443 | K30: =H30/G30 -> 5.1242398 | L30: 12.3 | M30: 251.6 | N30: =M30-L30 -> 239.3 | O30: =N30/(1+K30) -> 39.074237 | P30: =O30*1.5 -> 58.611356 | Q30: =O30+P30 -> 97.685594 | R30: =Q30+L30 -> 109.98559 | S30: 110 | T30: =S30-L30 -> 97.7 | U30: =(T30-O30)/O30 -> 1.5003687
A31: AT1_83-103 | B31: P23 | C31: 1.165 | D31: 8.696 | E31: 2.583 | F31: =E31/D31 -> 0.29703312 | G31: =E31-C31 -> 1.418 | H31: =D31-E31 -> 6.113 | I31: =H31/(E31-C31) -> 4.3110014 | J31: =H31/(D31-C31) -> 0.81171159 | K31: =H31/G31 -> 4.3110014 | L31: 12.3 | M31: 244.7 | N31: =M31-L31 -> 232.4 | O31: =N31/(1+K31) -> 43.758226 | P31: =O31*1.5 -> 65.637339 | Q31: =O31+P31 -> 109.39556 | R31: =Q31+L31 -> 121.69556 | S31: =129.2-(124.816-118.3) -> 122.684 | T31: =S31-L31 -> 110.384 | U31: =(T31-O31)/O31 -> 1.5225886
A32: AT1_143-163 | B32: P24 | C32: 1.172 | D32: 8.807 | E32: 2.031 | F32: =E32/D32 -> 0.23061201 | G32: =E32-C32 -> 0.859 | H32: =D32-E32 -> 6.776 | I32: =H32/(E32-C32) -> 7.8882421 | J32: =H32/(D32-C32) -> 0.88749181 | K32: =H32/G32 -> 7.8882421 | L32: 12.2 | M32: 239.6 | N32: =M32-L32 -> 227.4 | O32: =N32/(1+K32) -> 25.584361 | P32: =O32*1.5 -> 38.376542 | Q32: =O32+P32 -> 63.960904 | R32: =Q32+L32 -> 76.160904 | S32: 76.4 | T32: =S32-L32 -> 64.2 | U32: =(T32-O32)/O32 -> 1.5093454
A33: AT1_163-183 | B33: P25 | C33: 1.186 | D33: 10.884 | E33: 2.163 | F33: =E33/D33 -> 0.19873208 | G33: =E33-C33 -> 0.977 | H33: =D33-E33 -> 8.721 | I33: =H33/(E33-C33) -> 8.926305 | J33: =H33/(D33-C33) -> 0.89925758 | K33: =H33/G33 -> 8.926305 | L33: 12.2 | M33: 239.5 | N33: =M33-L33 -> 227.3 | O33: =N33/(1+K33) -> 22.898752 | P33: =O33*1.5 -> 34.348128 | Q33: =O33+P33 -> 57.246881 | R33: =Q33+L33 -> 69.446881 | S33: =74.6-(63.457-58.7) -> 69.843 | T33: =S33-L33 -> 57.643 | U33: =(T33-O33)/O33 -> 1.5172987
A34: AT2_0-40 | B34: P26 | C34: 1.183 | D34: 9.269 | E34: 1.737 | F34: =E34/D34 -> 0.18739886 | G34: =E34-C34 -> 0.554 | H34: =D34-E34 -> 7.532 | I34: =H34/(E34-C34) -> 13.595668 | J34: =H34/(D34-C34) -> 0.93148652 | K34: =H34/G34 -> 13.595668 | L34: 38.9 | M34: 585.3 | N34: =M34-L34 -> 546.4 | O34: =N34/(1+K34) -> 37.435766 | P34: =O34*2.5 -> 93.589414 | Q34: =O34+P34 -> 131.02518 | R34: =Q34+L34 -> 169.92518 | S34: =133.2+38.4 -> 171.6 | T34: =S34-L34 -> 132.7 | U34: =(T34-O34)/O34 -> 2.5447385
A35: AT2_43-63 | B35: P27 | C35: 1.168 | D35: 8.357 | E35: 2.788 | F35: =E35/D35 -> 0.33361254 | G35: =E35-C35 -> 1.62 | H35: =D35-E35 -> 5.569 | I35: =H35/(E35-C35) -> 3.4376543 | J35: =H35/(D35-C35) -> 0.77465572 | K35: =H35/G35 -> 3.4376543 | L35: 11 | M35: 170.8 | N35: =M35-L35 -> 159.8 | O35: =N35/(1+K35) -> 36.010015 | P35: =O35*1.5 -> 54.015023 | Q35: =O35+P35 -> 90.025038 | R35: =Q35+L35 -> 101.02504 | S35: =97.6+5.1 -> 102.7 | T35: =S35-L35 -> 91.7 | U35: =(T35-O35)/O35 -> 1.5465138
A36: AT2_63-83 | B36: P28 | C36: 1.183 | D36: 9.901 | E36: 2.807 | F36: =E36/D36 -> 0.28350672 | G36: =E36-C36 -> 1.624 | H36: =D36-E36 -> 7.094 | I36: =H36/(E36-C36) -> 4.3682266 | J36: =H36/(D36-C36) -> 0.81371874 | K36: =H36/G36 -> 4.3682266 | L36: 12.1 | M36: 214 | N36: =M36-L36 -> 201.9 | O36: =N36/(1+K36) -> 37.610186 | P36: =O36*1.5 -> 56.415279 | Q36: =O36+P36 -> 94.025465 | R36: =Q36+L36 -> 106.12546 | S36: 107.3 | T36: =S36-L36 -> 95.2 | U36: =(T36-O36)/O36 -> 1.5312292
A37: AT2_123-143 | B37: P29 | C37: 1.176 | D37: 10.293 | E37: 2.077 | F37: =E37/D37 -> 0.20178762 | G37: =E37-C37 -> 0.901 | H37: =D37-E37 -> 8.216 | I37: =H37/(E37-C37) -> 9.1187569 | J37: =H37/(D37-C37) -> 0.90117363 | K37: =H37/G37 -> 9.1187569 | L37: 12.2 | M37: 187.7 | N37: =M37-L37 -> 175.5 | O37: =N37/(1+K37) -> 17.344028 | P37: =O37*1.5 -> 26.016041 | Q37: =O37+P37 -> 43.360069 | R37: =Q37+L37 -> 55.560069 | S37: 56.4 | T37: =S37-L37 -> 44.2 | U37: =(T37-O37)/O37 -> 1.5484277
A38: AT2_143-163 | B38: P30 | C38: 1.178 | D38: 9.24 | E38: 2.034 | F38: =E38/D38 -> 0.22012987 | G38: =E38-C38 -> 0.856 | H38: =D38-E38 -> 7.206 | I38: =H38/(E38-C38) -> 8.4182243 | J38: =H38/(D38-C38) -> 0.89382287 | K38: =H38/G38 -> 8.4182243 | L38: 12.1 | M38: 271.7 | N38: =M38-L38 -> 259.6 | O38: =N38/(1+K38) -> 27.563582 | P38: =O38*1.5 -> 41.345373 | Q38: =O38+P38 -> 68.908956 | R38: =Q38+L38 -> 81.008956 | S38: 82.4 | T38: =S38-L38 -> 70.3 | U38: =(T38-O38)/O38 -> 1.5504667
A39: AT3_0-40 | B39: P31 | C39: 1.181 | D39: 8.822 | E39: 1.601 | F39: =E39/D39 -> 0.18147812 | G39: =E39-C39 -> 0.42 | H39: =D39-E39 -> 7.221 | I39: =H39/(E39-C39) -> 17.192857 | J39: =H39/(D39-C39) -> 0.94503337 | K39: =H39/G39 -> 17.192857 | L39: 25.4 | M39: 867.9 | N39: =M39-L39 -> 842.5 | O39: =N39/(1+K39) -> 46.309384 | P39: =O39*2.5 -> 115.77346 | Q39: =O39+P39 -> 162.08284 | R39: =Q39+L39 -> 187.48284 | S39: 188.4 | T39: =S39-L39 -> 163 | U39: =(T39-O39)/O39 -> 2.519805
A40: AT3_60-80 | B40: P32 | C40: 1.177 | D40: 8.992 | E40: 2.676 | F40: =E40/D40 -> 0.29759786 | G40: =E40-C40 -> 1.499 | H40: =D40-E40 -> 6.316 | I40: =H40/(E40-C40) -> 4.2134757 | J40: =H40/(D40-C40) -> 0.80818938 | K40: =H40/G40 -> 4.2134757 | L40: 12.1 | M40: 216.4 | N40: =M40-L40 -> 204.3 | O40: =N40/(1+K40) -> 39.18691 | P40: =O40*1.5 -> 58.780365 | Q40: =O40+P40 -> 97.967274 | R40: =Q40+L40 -> 110.06727 | S40: 111.5 | T40: =S40-L40 -> 99.4 | U40: =(T40-O40)/O40 -> 1.5365613
A41: AT3_80-100 | B41: P33 | C41: 1.19 | D41: 10.802 | E41: 2.905 | F41: =E41/D41 -> 0.26893168 | G41: =E41-C41 -> 1.715 | H41: =D41-E41 -> 7.897 | I41: =H41/(E41-C41) -> 4.6046647 | J41: =H41/(D41-C41) -> 0.8215772 | K41: =H41/G41 -> 4.6046647 | L41: 12.7 | M41: 215.9 | N41: =M41-L41 -> 203.2 | O41: =N41/(1+K41) -> 36.255514 | P41: =O41*1.5 -> 54.383271 | Q41: =O41+P41 -> 90.638785 | R41: =Q41+L41 -> 103.33878 | S41: 104.2 | T41: =S41-L41 -> 91.5 | U41: =(T41-O41)/O41 -> 1.523754
A42: AT3_140-160 | B42: P34 | C42: 1.178 | D42: 9.89 | E42: 2.034 | F42: =E42/D42 -> 0.20566229 | G42: =E42-C42 -> 0.856 | H42: =D42-E42 -> 7.856 | I42: =H42/(E42-C42) -> 9.1775701 | J42: =H42/(D42-C42) -> 0.90174472 | K42: =H42/G42 -> 9.1775701 | L42: 12.1 | M42: 242.6 | N42: =M42-L42 -> 230.5 | O42: =N42/(1+K42) -> 22.647842 | P42: =O42*1.5 -> 33.971763 | Q42: =O42+P42 -> 56.619605 | R42: =Q42+L42 -> 68.719605 | S42: 69.8 | T42: =S42-L42 -> 57.7 | U42: =(T42-O42)/O42 -> 1.5477041
...

Sheet 2_Water holding capacity
A1: Water holding capacity
A2: 45603
A3: Put in 5°C on 7.11., 14:30h
A4: Taken out on 8.11., 11:15h
A7: Sample ID | B7: Working ID | C7: Nr. glass | D7: Glass empty [g] | E7: Glass empty + filter dry [g] | F7: Glass empty + filter wet [g] | G7: Weight sample (no glass + filter) [g] | H7: Weight sample wet + glass + filter [g] | I7: Weight sample wet (no glass, filter) [g] | J7: Weight sample after draining + glass + filter [g] | K7: Weight sample after draining (no glass, filter) [g]
A8: AP1_0-20 | B8: P1 | C8: 29 | D8: 13.979 | E8: 13.991 | F8: =D8+0.0865 -> 14.0655 | G8: 0.812 | H8: 16.544 | I8: =H8-F8 -> 2.4785 | J8: 15.503 | K8: =J8-F8 -> 1.4375 | L8: =K8-G8 -> 0.6255
A9: AP1_20-40 | B9: P2 | C9: 30 | D9: 13.944 | E9: 13.956 | F9: =D9+0.0865 -> 14.0305 | G9: 1.128 | H9: 16.597 | I9: =H9-F9 -> 2.5665 | J9: 16.453 | K9: =J9-F9 -> 2.4225 | L9: =K9-G9 -> 1.2945
A10: AP3_0-20 | B10: P11 | C10: 47 | D10: 13.976 | E10: 13.987 | F10: =D10+0.0865 -> 14.0625 | G10: 0.692 | H10: 16 | I10: =H10-F10 -> 1.9375 | J10: 15.672 | K10: =J10-F10 -> 1.6095 | L10: =K10-G10 -> 0.9175
A11: AP3_20-40 | B11: P12 | C11: 49 | D11: 13.959 | E11: 13.971 | F11: =D11+0.0865 -> 14.0455 | G11: 1.363 | H11: 16.951 | I11: =H11-F11 -> 2.9055 | J11: 16.547 | K11: =J11-F11 -> 2.5015 | L11: =K11-G11 -> 1.1385
A17: Water content | M17: Drying of samples for analyses
A18: 45604 | M18: 45608
A19: Put in 105 °C after determination of water holding capacity on 8.11., 11:25h | M19: Weighing of total samples into aluminum bowls and drying
A20: Taken out 11.11.24; 8:00h
A22: Sample ID | B22: Working ID | C22: Weight bowl empty [g] | D22: Fresh weight + bowl [g] | E22: Dry weight + bowl [g] | F22: Dry weight [%] | G22: Dry weight [g] | H22: Absolute mass water [g] | I22: Absolute mass water at max. WHC [g] | J22: gravimetric water content [g/g] | K22: water content at max. WHC [%] | L22: WHC [g/g] | M22: Weight bowl [g] | N22: Total weight sample + bowl [g] | O22: Total weight sample [g] | P22: Total dry weight [g] | Q22: Water content at 150% [g] | R22: Weight of sample at 150% water content [g] | S22: Weight of sample + bowl at 150% water content [g] | T22: Weight of sample + bowl after drying [g] | U22: Weight of sample after drying [g] | V22: Water content [g/g] | W22: Attention: water content of aerobic samples lower after pre-incubation (see table 3)
A23: AP1_0-20 | B23: P1 | C23: =D8 -> 13.979 | D23: =J8 -> 15.503 | E23: 14.158 | F23: =E23/D23 -> 0.9132426 | G23: =E23-C23 -> 0.179 | H23: =G8-G23 -> 0.633 | I23: =D23-E23 -> 1.345 | J23: =H23/G23 -> 3.5363128 | K23: =I23/(D23-C23) -> 0.88254593 | L23: =I23/G23 -> 7.5139665 | M23: 38.9 | N23: 265.1 | O23: =N23-M23 -> 226.2 | P23: =O23/(1+J23) -> 49.864286 | Q23: =P23*1.5 -> 74.796429 | R23: =P23+Q23 -> 124.66071 | S23: =R23+M23 -> 163.56071 | T23: =144.2+20.3 -> 164.5 | U23: =T23-M23 -> 125.6 | V23: =(U23-P23)/P23 -> 1.5188368
A24: AP1_20-40 | B24: P2 | C24: =D9 -> 13.944 | D24: =J9 -> 16.453 | E24: 14.115 | F24: =E24/D24 -> 0.85789826 | G24: =E24-C24 -> 0.171 | H24: =G9-G24 -> 0.957 | I24: =D24-E24 -> 2.338 | J24: =H24/G24 -> 5.5964912 | K24: =I24/(D24-C24) -> 0.93184536 | L24: =I24/G24 -> 13.672515 | M24: 38.4 | N24: 403.1 | O24: =N24-M24 -> 364.7 | P24: =O24/(1+J24) -> 55.286968 | Q24: =P24*1.5 -> 82.930452 | R24: =P24+Q24 -> 138.21742 | S24: =R24+M24 -> 176.61742 | T24: 177.2 | U24: =T24-M24 -> 138.8 | V24: =(U24-P24)/P24 -> 1.5105374
A25: AP3_0-20 | B25: P11 | C25: =D10 -> 13.976 | D25: =J10 -> 15.672 | E25: 14.147 | F25: =E25/D25 -> 0.9026927 | G25: =E25-C25 -> 0.171 | H25: =G10-G25 -> 0.521 | I25: =D25-E25 -> 1.525 | J25: =H25/G25 -> 3.0467836 | K25: =I25/(D25-C25) -> 0.89917453 | L25: =I25/G25 -> 8.9181287 | M25: 39 | N25: 195.7 | O25: =N25-M25 -> 156.7 | P25: =O25/(1+J25) -> 38.72211 | Q25: =P25*1.5 -> 58.083165 | R25: =P25+Q25 -> 96.805275 | S25: =R25+M25 -> 135.80527 | T25: =125.3+11.1 -> 136.4 | U25: =T25-M25 -> 97.4 | V25: =(U25-P25)/P25 -> 1.5153588
A26: AP3_20-40 | B26: P12 | C26: =D11 -> 13.959 | D26: =J11 -> 16.547 | E26: 14.16 | F26: =E26/D26 -> 0.85574424 | G26: =E26-C26 -> 0.201 | H26: =G11-G26 -> 1.162 | I26: =D26-E26 -> 2.387 | J26: =H26/G26 -> 5.7810945 | K26: =I26/(D26-C26) -> 0.92233385 | L26: =I26/G26 -> 11.875622 | M26: 38.4 | N26: 381.5 | O26: =N26-M26 -> 343.1 | P26: =O26/(1+J26) -> 50.596552 | Q26: =P26*1.5 -> 75.894828 | R26: =P26+Q26 -> 126.49138 | S26: =R26+M26 -> 164.89138 | T26: 165.3 | U26: =T26-M26 -> 126.9 | V26: =(U26-P26)/P26 -> 1.5080761

Sheet 3_Pre-incubation
A1: Pre-incubation
A2: 45614
A3: Weighing 10-15 g of samples into 100ml shot-glasses
A4: Incubating at 15 °C
A5: Start aerobic samples: 18.11., 17h/ 19.11., 12.30h (P1, P2, P11, P12, P14, P15, P18, P19, P25, P39)
A6: End aerobic samples: 27.11., 7:30
A7: Start anaerobic samples 19.11., 14h
A8: End anaerobic samples 9.12., 12:55h
A11: Sample ID | B11: Working ID | C11: Incubation ID | D11: O2 conditions | E11: Weight glas (without lid, septum) [g] | F11: Weight sample [g] | G11: Weight sample + glas [g] | H11: Weight sample + glas after pre-incubation [g] | I11: Weight loss [g] | J11: water content before pre-incubation [g/g] | K11: water content after pre-incubation [g/g]
A12: AP1_0-20 | B12: P1 | C12: A1 | D12: aerobic | E12: 145.344 | F12: 14.716 | G12: =E12+F12 -> 160.06 | H12: 159.964 | I12: =G12-H12 -> 0.096 | J12: 1.5188368 | K12: =(J12/G12)*H12 -> 1.5179259
A13: AP1_20-40 | B13: P2 | C13: A2 | D13: aerobic | E13: 148.485 | F13: 12.209 | G13: =E13+F13 -> 160.694 | H13: 160.526 | I13: =G13-H13 -> 0.168 | J13: 1.5105374 | K13: =(J13/G13)*H13 -> 1.5089582
A14: AP1_50-69 | B14: P3 | C14: A3 | D14: aerobic | E14: 146.568 | F14: 16.042 | G14: =E14+F14 -> 162.61 | H14: 162.394 | I14: =G14-H14 -> 0.216 | J14: 1.5318842 | K14: =(J14/G14)*H14 -> 1.5298493
A15: AP1_80-100 | B15: P4 | C15: A4 | D15: aerobic | E15: 145.041 | F15: 15.372 | G15: =E15+F15 -> 160.413 | H15: 160.222 | I15: =G15-H15 -> 0.191 | J15: 1.5675593 | K15: =(J15/G15)*H15 -> 1.5656928
A16: AP1_100-120 | B16: P5 | C16: A5 | D16: aerobic | E16: 146.021 | F16: 15.25 | G16: =E16+F16 -> 161.271 | H16: 161.145 | I16: =G16-H16 -> 0.126 | J16: 1.5120188 | K16: =(J16/G16)*H16 -> 1.5108375
A17: AP2_0-20 | B17: P16 | C17: A6 | D17: aerobic | E17: 144.807 | F17: 15.063 | G17: =E17+F17 -> 159.87 | H17: 159.69 | I17: =G17-H17 -> 0.18 | J17: 1.5096121 | K17: =(J17/G17)*H17 -> 1.5079124
A18: AP2_20-40 | B18: P7 | C18: A7 | D18: aerobic | E18: 144.735 | F18: 15.548 | G18: =E18+F18 -> 160.283 | H18: 160.017 | I18: =G18-H18 -> 0.266 | J18: 1.5013297 | K18: =(J18/G18)*H18 -> 1.4988381
A19: AP2_50-69 | B19: P8 | C19: A8 | D19: aerobic | E19: 144.674 | F19: 15.054 | G19: =E19+F19 -> 159.728 | H19: 159.578 | I19: =G19-H19 -> 0.15 | J19: 1.5697506 | K19: =(J19/G19)*H19 -> 1.5682765
A20: AP2_80-100 | B20: P9 | C20: A9 | D20: aerobic | E20: 147.588 | F20: 14.821 | G20: =E20+F20 -> 162.409 | H20: 162.212 | I20: =G20-H20 -> 0.197 | J20: 1.5319529 | K20: =(J20/G20)*H20 -> 1.5300947
A21: AP2_100-120 | B21: P10 | C21: A10 | D21: aerobic | E21: 144.79 | F21: 14.621 | G21: =E21+F21 -> 159.411 | H21: 159.247 | I21: =G21-H21 -> 0.164 | J21: 1.4987584 | K21: =(J21/G21)*H21 -> 1.4972165
A22: AP3_0-20 | B22: P11 | C22: A11 | D22: aerobic | E22: 145.984 | F22: 12.425 | G22: =E22+F22 -> 158.409 | H22: 158.234 | I22: =G22-H22 -> 0.175 | J22: 1.5153588 | K22: =(J22/G22)*H22 -> 1.5136847
A23: AP3_20-40 | B23: P12 | C23: A12 | D23: aerobic | E23: 145.203 | F23: 12.89 | G23: =E23+F23 -> 158.093 | H23: 157.885 | I23: =G23-H23 -> 0.208 | J23: 1.5080761 | K23: =(J23/G23)*H23 -> 1.5060919
... A39: AT5_150-170 | B39: P40 | C39: A28 | D39: aerobic | E39: 146.143 | F39: 10.815 | G39: =E39+F39 -> 156.958 | H39: 156.684 | I39: =G39-H39 -> 0.274 | J39: 1.5216308 | K39: =(J39/G39)*H39 -> 1.5189745
A40: AT1_0-40 | B40: P21 | C40: A29 | D40: anaerobic | E40: 146.203 | F40: 11.106 | G40: =E40+F40 -> 157.309
A41: AT1_63-83 | B41: P22 | C41: A30 | D41: anaerobic | E41: 145.339 | F41: 14.369 | G41: =E41+F41 -> 159.708
A42: AT1_83-103 | B42: P23 | C42: A31 | D42: anaerobic | E42: 144.727 | F42: 13.231 | G42: =E42+F42 -> 157.958
A43: AT1_143-163 | B43: P24 | C43: A32 | D43: anaerobic | E43: 145.579 | F43: 12.504 | G43: =E43+F43 -> 158.083
A44: AT1_163-183 | B44: P25 | C44: A33 | D44: anaerobic | E44: 145.298 | F44: 12.103 | G44: =E44+F44 -> 157.401
A45: AT2_0-40 | B45: P26 | C45: A34 | D45: anaerobic | E45: 145.633 | F45: 13.076 | G45: =E45+F45 -> 158.709
A46: AT2_43-63 | B46: P27 | C46: A35 | D46: anaerobic | E46: 144.811 | F46: 13.248 | G46: =E46+F46 -> 158.059
A47: AT2_63-83 | B47: P28 | C47: A36 | D47: anaerobic | E47: 145.418 | F47: 16.301 | G47: =E47+F47 -> 161.719
A48: AT2_123-143 | B48: P29 | C48: A37 | D48: anaerobic | E48: 145.367 | F48: 12.224 | G48: =E48+F48 -> 157.591
A49: AT2_143-163 | B49: P30 | C49: A38 | D49: anaerobic | E49: 146.434 | F49: 13.057 | G49: =E49+F49 -> 159.491
A50: AT3_0-40 | B50: P31 | C50: A39 | D50: anaerobic | E50: 145.932 | F50: 14.307 | G50: =E50+F50 -> 160.239
A51: AT3_60-80 | B51: P32 | C51: A40 | D51: anaerobic | E51: 144.817 | F51: 16.312 | G51: =E51+F51 -> 161.129
... A67: AP4_99-120 | B67: P20 | C67: A56 | D67: anaerobic | E67: 145.817 | F67: 9.592 | G67: =E67+F67 -> 155.409

Sheet 4_DNA-Extraction 
A1: DNA-Extraction aerobic | G1: Notes: | H1: exactly 700ul of supernatant could not be taken from all the samples --> in the next steps also not exactly 700ul of sample | V1: DNA-Extraction anaerobic | AE1: Notes: | AF1: exactly 700ul of supernatant could not be taken from all the samples --> in the next steps also not exactly 700ul of sample
A2: 29.11.2024 weighing (samples 1-36) | H2: For samples 17, 18, 23, 24 and additional amount of 300 ul lysing buffer had to be added to get enough supernatant | V2: 19.11.2024 Weighing of ca. 350 mg sample into small glasses, flushing with N2 and pre-incubating at 15 °C | AF2: Extracted DNA samples were still quite dark, especially 69, 70, 71, 72
A3: 2.12.2024 weighing samples (37-56) | H3: Extracted DNA samples were still quite dark, especiall 11, 12, 13, 14, 31, 32, 33, 34 | V3: 3.12.2024, 15:55 start incubation 18O third batch (samples 57-84) | AF3: For purification of 4th batch, 80ul of DNA were added (instead of 70), 240ul of Nal solution were used (instead of 210) and the samples were vortexed instead of shaken
A4: 2.12.2024, 10:56 start incubation 18O first batch (samples 1-28) | V4: 3.12.2024, 15:42 start incubation 16O third batch (samples 57-84)
A5: 2.12.2024, 11:03 start incubation 16O first batch (samples 1-28) | V5: 6.12.2024, 8:09 end of incubation third batch (samples 57-84)
A6: 4.12.2024, 11:01 end of incubation first batch (samples 1-28) | V6: 10.12.2024, 16:07 start incubation 18O fourth batch (samples 85-112)
A7: 5.12.2024, purification first batch | V7: 10.12.2024, 15:47 start incubation 16O fourth batch (samples 85-112)
A8: 3.12.2024, 7:59 start incubation 18O second batch (sampes 29-56) | V8: 13.12.2024, 8:04 end of incubation fourth batch (samples 85-112)
A9: 3.12.2024, 8:08 start of incubation 16O second batch (samples 29-56)
A10: 5.12.2024, 8:01 end of incubation second batch (samples 29-56)
A11: 11.12.2024, 8:00 start incubation 18O sample 36
A12: 11.12.2024, 8:01 start incubation 16O sample 35
A13: 13.12.2024, 8:04 end incubation sample 35, 36
Q15: Purification | AO15: Purification
A16: Sample ID | B16: Working ID | C16: Incubation ID | D16: O2 conditions | E16: DNA ID | F16: DNA ID 2 | G16: 18O Label | H16: Weight [g] | I16: Weight [mg] | J16: Water content [g/g] | K16: Dry weight [g] | L16: Water [g] | M16: 18O/16O addition [ul] | N16: Weight E-tube empty [g] | O16: Weight E-tube after extraction [g] | P16: Weight extracted DNA [g] | Q16: Weight E-tube empty [g] | R16: Weight E-tube after purification [g] | S16: Weight DNA [g] | V16: Sample ID | W16: Working ID | X16: Incubation ID | Y16: O2 conditions | Z16: DNA ID | AA16: DNA ID 2 | AB16: 18O Label | AC16: Weight pre-incubation [g] | AD16: Water content [g/g] | AE16: Dry weight [g] | AF16: Water [g] | AG16: 18O/16O addition [ul] | AH16: Weight after incubation total (in correct tubes for extraction, including added water) [g] | AI16: Weight after incubation only soil (no 18O/16O addition) [g] | AJ16: Weight after incubation only soil (no 18O/16O addition) [mg] | AK16: Dry weight after incubation (in correct tubes for extraction, including added water) [g] | AL16: Weight E-tube empty [g] | AM16: Weight E-tube after extraction [g] | AN16: Weight extracted DNA [g] | AO16: Weight E-tube empty [g] | AP16: Weight E-tube after purification [g] | AQ16: Weight DNA [g]
A17: AP1_0-20 | B17: P1 | C17: A1 | D17: aerobic | E17: A1 | F17: 1 | G17: No | H17: 0.3503 | I17: =H17*1000 -> 350.3 | J17: ='3_Pre-incubation'!K12 -> 1.5179259 | K17: =H17/(1+J17) -> 0.13912244 | L17: =K17*J17 -> 0.21117756 | M17: 150 | N17: 0.9832 | O17: 1.0759 | P17: =O17-N17 -> 0.0927 | Q17: 0.9722 | R17: 1.0172 | S17: =R17-Q17 -> 0.045 | V17: AT1_0-40 | W17: P21 | X17: A29 | Y17: anaerobic | Z17: A29 | AA17: 57 | AB17: No | AC17: 0.3538 | AD17: 2.5392545 | AE17: =AC17/(1+AD17) -> 0.099964554 | AF17: =AE17*AD17 -> 0.25383545 | AG17: 149 | AH17: 0.3665 | AI17: =AH17-((AG17/1000)/(AC17+AG17/1000))*AH17 -> 0.25789121 | AJ17: =AI17*1000 -> 257.89121 | AK17: =((AH17)-((AG17/1000)/(AE17+AF17+AG17/1000)*AH17))/(1+AD17) -> 0.072865968 | AL17: 0.9808 | AM17: 1.0758 | AN17: =AM17-AL17 -> 0.095 | AO17: 0.9791 | AP17: 1.0268 | AQ17: =AP17-AO17 -> 0.0477
A18: AP1_0-20 | B18: P1 | C18: A1 | D18: aerobic | E18: A1 x | F18: 2 | G18: Yes | H18: 0.3607 | I18: =H18*1000 -> 360.7 | J18: =J17 -> 1.5179259 | K18: =H18/(1+J18) -> 0.14325283 | L18: =K18*J18 -> 0.21744717 | M18: 150 | N18: 0.9856 | O18: 1.0884 | P18: =O18-N18 -> 0.1028 | Q18: 0.9827 | R18: 1.0285 | S18: =R18-Q18 -> 0.0458 | V18: AT1_0-40 | W18: P21 | X18: A29 | Y18: anaerobic | Z18: A29 x | AA18: 58 | AB18: Yes | AC18: =0.3865-0.0214 -> 0.3651 | AD18: 2.5392545 | AE18: =AC18/(1+AD18) -> 0.10315732 | AF18: =AE18*AD18 -> 0.26194268 | AG18: 162 | AH18: 0.3541 | AI18: =AH18-((AG18/1000)/(AC18+AG18/1000))*AH18 -> 0.24527018 | AJ18: =AI18*1000 -> 245.27018 | AK18: =((AH18)-((AG18/1000)/(AE18+AF18+AG18/1000)*AH18))/(1+AD18) -> 0.069299954 | AL18: 0.9817 | AM18: 1.0781 | AN18: =AM18-AL18 -> 0.0964 | AO18: 0.9796 | AP18: 1.0274 | AQ18: =AP18-AO18 -> 0.0478
A19: AP1_20-40 | B19: P2 | C19: A2 | D19: aerobic | E19: A2 | F19: 3 | G19: No | H19: 0.3546 | I19: =H19*1000 -> 354.6 | J19: ='3_Pre-incubation'!K13 -> 1.5089582 | K19: =H19/(1+J19) -> 0.14133356 | L19: =K19*J19 -> 0.21326644 | M19: 150 | N19: 0.9772 | O19: 1.0756 | P19: =O19-N19 -> 0.0984 | Q19: 0.9834 | R19: 1.0307 | S19: =R19-Q19 -> 0.0473 | V19: AT1_63-83 | W19: P22 | X19: A30 | Y19: anaerobic | Z19: A30 | AA19: 59 | AB19: No | AC19: 0.375 | AD19: 1.5003687 | AE19: =AC19/(1+AD19) -> 0.14997788 | AF19: =AE19*AD19 -> 0.22502212 | AG19: 147 | AH19: 0.4165 | AI19: =AH19-((AG19/1000)/(AC19+AG19/1000))*AH19 -> 0.29920977 | AJ19: =AI19*1000 -> 299.20977 | AK19: =((AH19)-((AG19/1000)/(AE19+AF19+AG19/1000)*AH19))/(1+AD19) -> 0.11966626 | AL19: 0.9833 | AM19: 1.0786 | AN19: =AM19-AL19 -> 0.0953 | AO19: 0.986 | AP19: 1.0345 | AQ19: =AP19-AO19 -> 0.0485
A20: AP1_20-40 | B20: P2 | C20: A2 | D20: aerobic | E20: A2 x | F20: 4 | G20: Yes | H20: 0.3539 | I20: =H20*1000 -> 353.9 | J20: =J19 -> 1.5089582 | K20: =H20/(1+J20) -> 0.14105456 | L20: =K20*J20 -> 0.21284544 | M20: 150 | N20: 0.9766 | O20: 1.0686 | P20: =O20-N20 -> 0.092 | Q20: 0.9825 | R20: 1.0278 | S20: =R20-Q20 -> 0.0453 | V20: AT1_63-83 | W20: P22 | X20: A30 | Y20: anaerobic | Z20: A30 x | AA20: 60 | AB20: Yes | AC20: =0.398-0.0362 -> 0.3618 | AD20: 1.5003687 | AE20: =AC20/(1+AD20) -> 0.14469866 | AF20: =AE20*AD20 -> 0.21710134 | AG20: 135 | AH20: 0.4134 | AI20: =AH20-((AG20/1000)/(AC20+AG20/1000))*AH20 -> 0.30106304 | AJ20: =AI20*1000 -> 301.06304 | AK20: =((AH20)-((AG20/1000)/(AE20+AF20+AG20/1000)*AH20))/(1+AD20) -> 0.12040746 | AL20: 0.9755 | AM20: 1.0706 | AN20: =AM20-AL20 -> 0.0951 | AO20: 0.9825 | AP20: 1.0306 | AQ20: =AP20-AO20 -> 0.0481
A21: AP1_50-69 | B21: P3 | C21: A3 | D21: aerobic | E21: A3 | F21: 5 | G21: No | H21: 0.3554 | I21: =H21*1000 -> 355.4 | J21: ='3_Pre-incubation'!K14 -> 1.5298493 | K21: =H21/(1+J21) -> 0.14048268 | L21: =K21*J21 -> 0.21491732 | M21: 150 | N21: 0.9837 | O21: 1.0749 | P21: =O21-N21 -> 0.0912 | Q21: 0.9791 | R21: 1.025 | S21: =R21-Q21 -> 0.0459 | V21: AT1_83-103 | W21: P23 | X21: A31 | Y21: anaerobic | Z21: A31 | AA21: 61 | AB21: No | AC21: 0.3735 | AD21: 1.5225886 | AE21: =AC21/(1+AD21) -> 0.1480622 | AF21: =AE21*AD21 -> 0.2254378 | AG21: 145 | AH21: 0.3648 | AI21: =AH21-((AG21/1000)/(AC21+AG21/1000))*AH21 -> 0.26278264 | AJ21: =AI21*1000 -> 262.78264 | AK21: =((AH21)-((AG21/1000)/(AE21+AF21+AG21/1000)*AH21))/(1+AD21) -> 0.10417182 | AL21: 0.9822 | AM21: 1.0778 | AN21: =AM21-AL21 -> 0.0956 | AO21: 0.9824 | AP21: 1.0303 | AQ21: =AP21-AO21 -> 0.0479
A22: AP1_50-69 | B22: P3 | C22: A3 | D22: aerobic | E22: A3 x | F22: 6 | G22: Yes | H22: 0.3558 | I22: =H22*1000 -> 355.8 | J22: =J21 -> 1.5298493 | K22: =H22/(1+J22) -> 0.14064079 | L22: =K22*J22 -> 0.21515921 | M22: 150 | N22: 0.9817 | O22: 1.0731 | P22: =O22-N22 -> 0.0914 | Q22: 0.9799 | R22: 1.0267 | S22: =R22-Q22 -> 0.0468 | V22: AT1_83-103 | W22: P23 | X22: A31 | Y22: anaerobic | Z22: A31 x | AA22: 62 | AB22: Yes | AC22: 0.3603 | AD22: 1.5225886 | AE22: =AC22/(1+AD22) -> 0.14282948 | AF22: =AE22*AD22 -> 0.21747052 | AG22: 162 | AH22: 0.3848 | AI22: =AH22-((AG22/1000)/(AC22+AG22/1000))*AH22 -> 0.2654479 | AJ22: =AI22*1000 -> 265.4479 | AK22: =((AH22)-((AG22/1000)/(AE22+AF22+AG22/1000)*AH22))/(1+AD22) -> 0.10522838 | AL22: 0.9821 | AM22: 1.0769 | AN22: =AM22-AL22 -> 0.0948 | AO22: 0.9799 | AP22: 1.0276 | AQ22: =AP22-AO22 -> 0.0477
A23: AP1_80-100 | B23: P4 | C23: A4 | D23: aerobic | E23: A4 | F23: 7 | G23: No | H23: 0.3529 | I23: =H23*1000 -> 352.9 | J23: ='3_Pre-incubation'!K15 -> 1.5656928 | K23: =H23/(1+J23) -> 0.13754569 | L23: =K23*J23 -> 0.21535431 | M23: 150 | N23: 0.9809 | O23: 1.0745 | P23: =O23-N23 -> 0.0936 | Q23: 0.9803 | R23: 1.0265 | S23: =R23-Q23 -> 0.0462 | V23: AT1_143-163 | W23: P24 | X23: A32 | Y23: anaerobic | Z23: A32 | AA23: 63 | AB23: No | AC23: 0.373 | AD23: 1.5093454 | AE23: =AC23/(1+AD23) -> 0.14864434 | AF23: =AE23*AD23 -> 0.22435566 | AG23: 148 | AH23: 0.3617 | AI23: =AH23-((AG23/1000)/(AC23+AG23/1000))*AH23 -> 0.25895221 | AJ23: =AI23*1000 -> 258.95221 | AK23: =((AH23)-((AG23/1000)/(AE23+AF23+AG23/1000)*AH23))/(1+AD23) -> 0.10319512 | AL23: 0.9827 | AM23: 1.0781 | AN23: =AM23-AL23 -> 0.0954 | AO23: 0.9791 | AP23: 1.0267 | AQ23: =AP23-AO23 -> 0.0476
A24: AP1_80-100 | B24: P4 | C24: A4 | D24: aerobic | E24: A4 x | F24: 8 | G24: Yes | H24: 0.3472 | I24: =H24*1000 -> 347.2 | J24: =J23 -> 1.5656928 | K24: =H24/(1+J24) -> 0.13532407 | L24: =K24*J24 -> 0.21187593 | M24: 150 | N24: 0.9789 | O24: 1.0713 | P24: =O24-N24 -> 0.0924 | Q24: 0.9825 | R24: 1.0297 | S24: =R24-Q24 -> 0.0472 | V24: AT1_143-163 | W24: P24 | X24: A32 | Y24: anaerobic | Z24: A32 x | AA24: 64 | AB24: Yes | AC24: 0.364 | AD24: 1.5093454 | AE24: =AC24/(1+AD24) -> 0.14505775 | AF24: =AE24*AD24 -> 0.21894225 | AG24: 134 | AH24: 0.3506 | AI24: =AH24-((AG24/1000)/(AC24+AG24/1000))*AH24 -> 0.25626185 | AJ24: =AI24*1000 -> 256.26185 | AK24: =((AH24)-((AG24/1000)/(AE24+AF24+AG24/1000)*AH24))/(1+AD24) -> 0.10212299 | AL24: 0.9803 | AM24: 1.0763 | AN24: =AM24-AL24 -> 0.096 | AO24: 0.9794 | AP24: 1.0272 | AQ24: =AP24-AO24 -> 0.0478
A25: AP1_100-120 | B25: P5 | C25: A5 | D25: aerobic | E25: A5 | F25: 9 | G25: No | H25: 0.3494 | I25: =H25*1000 -> 349.4 | J25: ='3_Pre-incubation'!K16 -> 1.5108375 | K25: =H25/(1+J25) -> 0.13915676 | L25: =K25*J25 -> 0.21024324 | M25: 150 | N25: 0.9811 | O25: 1.0745 | P25: =O25-N25 -> 0.0934 | Q25: 0.986 | R25: 1.0326 | S25: =R25-Q25 -> 0.0466 | V25: AT1_163-183 | W25: P25 | X25: A33 | Y25: anaerobic | Z25: A33 | AA25: 65 | AB25: No | AC25: 0.3642 | AD25: 1.5172987 | AE25: =AC25/(1+AD25) -> 0.1446789 | AF25: =AE25*AD25 -> 0.2195211 | AG25: 151 | AH25: 0.3983 | AI25: =AH25-((AG25/1000)/(AC25+AG25/1000))*AH25 -> 0.28156223 | AJ25: =AI25*1000 -> 281.56223 | AK25: =((AH25)-((AG25/1000)/(AE25+AF25+AG25/1000)*AH25))/(1+AD25) -> 0.11185094 | AL25: 0.9798 | AM25: 1.0752 | AN25: =AM25-AL25 -> 0.0954 | AO25: 0.9857 | AP25: 1.0331 | AQ25: =AP25-AO25 -> 0.0474
A26: AP1_100-120 | B26: P5 | C26: A5 | D26: aerobic | E26: A5 x | F26: 10 | G26: Yes | H26: 0.3533 | I26: =H26*1000 -> 353.3 | J26: =J25 -> 1.5108375 | K26: =H26/(1+J26) -> 0.14071002 | L26: =K26*J26 -> 0.21258998 | M26: 150 | N26: 0.9808 | O26: 1.074 | P26: =O26-N26 -> 0.0932 | Q26: 0.982 | R26: 1.0302 | S26: =R26-Q26 -> 0.0482 | V26: AT1_163-183 | W26: P25 | X26: A33 | Y26: anaerobic | Z26: A33 x | AA26: 66 | AB26: Yes | AC26: =0.3767-0.0106 -> 0.3661 | AD26: 1.5172987 | AE26: =AC26/(1+AD26) -> 0.14543367 | AF26: =AE26*AD26 -> 0.22066633 | AG26: 130 | AH26: 0.4195 | AI26: =AH26-((AG26/1000)/(AC26+AG26/1000))*AH26 -> 0.30957257 | AJ26: =AI26*1000 -> 309.57257 | AK26: =((AH26)-((AG26/1000)/(AE26+AF26+AG26/1000)*AH26))/(1+AD26) -> 0.12297808 | AL26: 0.985 | AM26: 1.0795 | AN26: =AM26-AL26 -> 0.0945 | AO26: 0.9727 | AP26: 1.0195 | AQ26: =AP26-AO26 -> 0.0468
A27: AP2_0-20 | B27: P16 | C27: A6 | D27: aerobic | E27: A6 | F27: 11 | G27: No | H27: 0.3559 | I27: =H27*1000 -> 355.9 | J27: ='3_Pre-incubation'!K17 -> 1.5079124 | K27: =H27/(1+J27) -> 0.14191086 | L27: =K27*J27 -> 0.21398914 | M27: 150 | N27: 0.9837 | O27: 1.0744 | P27: =O27-N27 -> 0.0907 | Q27: 0.9732 | R27: 1.0193 | S27: =R27-Q27 -> 0.0461 | V27: AT2_0-40 | W27: P26 | X27: A34 | Y27: anaerobic | Z27: A34 | AA27: 67 | AB27: No | AC27: 0.3721 | AD27: 2.5447385 | AE27: =AC27/(1+AD27) -> 0.10497248 | AF27: =AE27*AD27 -> 0.26712752 | AG27: 148 | AH27: 0.4126 | AI27: =AH27-((AG27/1000)/(AC27+AG27/1000))*AH27 -> 0.29519027 | AJ27: =AI27*1000 -> 295.19027 | AK27: =((AH27)-((AG27/1000)/(AE27+AF27+AG27/1000)*AH27))/(1+AD27) -> 0.083275612 | AL27: 0.9857 | AM27: 1.0797 | AN27: =AM27-AL27 -> 0.094 | AO27: 0.9824 | AP27: 1.0294 | AQ27: =AP27-AO27 -> 0.047
A28: AP2_0-20 | B28: P16 | C28: A6 | D28: aerobic | E28: A6 x | F28: 12 | G28: Yes | H28: 0.3522 | I28: =H28*1000 -> 352.2 | J28: =J27 -> 1.5079124 | K28: =H28/(1+J28) -> 0.14043553 | L28: =K28*J28 -> 0.21176447 | M28: 150 | N28: 0.9835 | O28: 1.0734 | P28: =O28-N28 -> 0.0899 | Q28: 0.9801 | R28: 1.0293 | S28: =R28-Q28 -> 0.0492 | V28: AT2_0-40 | W28: P26 | X28: A34 | Y28: anaerobic | Z28: A34 x | AA28: 68 | AB28: Yes | AC28: 0.369 | AD28: 2.5447385 | AE28: =AC28/(1+AD28) -> 0.10409795 | AF28: =AE28*AD28 -> 0.26490205 | AG28: 139 | AH28: 0.4454 | AI28: =AH28-((AG28/1000)/(AC28+AG28/1000))*AH28 -> 0.32352874 | AJ28: =AI28*1000 -> 323.52874 | AK28: =((AH28)-((AG28/1000)/(AE28+AF28+AG28/1000)*AH28))/(1+AD28) -> 0.091270129 | AL28: 0.9767 | AM28: 1.0734 | AN28: =AM28-AL28 -> 0.0967 | AO28: 0.9772 | AP28: 1.0248 | AQ28: =AP28-AO28 -> 0.0476
A29: AP2_20-40 | B29: P7 | C29: A7 | D29: aerobic | E29: A7 | F29: 13 | G29: No | H29: 0.3544 | I29: =H29*1000 -> 354.4 | J29: ='3_Pre-incubation'!K18 -> 1.4988381 | K29: =H29/(1+J29) -> 0.14182591 | L29: =K29*J29 -> 0.21257409 | M29: 150 | N29: 0.9868 | O29: 1.0786 | P29: =O29-N29 -> 0.0918 | Q29: 0.9782 | R29: 1.0235 | S29: =R29-Q29 -> 0.0453 | V29: AT2_43-63 | W29: P27 | X29: A35 | Y29: anaerobic | Z29: A35 | AA29: 69 | AB29: No | AC29: 0.369 | AD29: 1.5465138 | AE29: =AC29/(1+AD29) -> 0.14490399 | AF29: =AE29*AD29 -> 0.22409601 | AG29: 145 | AH29: 0.377 | AI29: =AH29-((AG29/1000)/(AC29+AG29/1000))*AH29 -> 0.27064786 | AJ29: =AI29*1000 -> 270.64786 | AK29: =((AH29)-((AG29/1000)/(AE29+AF29+AG29/1000)*AH29))/(1+AD29) -> 0.10628172 | AL29: 0.9817 | AM29: 1.0727 | AN29: =AM29-AL29 -> 0.091 | AO29: 0.9793 | AP29: 1.022 | AQ29: =AP29-AO29 -> 0.0427
A30: AP2_20-40 | B30: P7 | C30: A7 | D30: aerobic | E30: A7 x | F30: 14 | G30: Yes | H30: 0.3454 | I30: =H30*1000 -> 345.4 | J30: =J29 -> 1.4988381 | K30: =H30/(1+J30) -> 0.13822424 | L30: =K30*J30 -> 0.20717576 | M30: 150 | N30: 0.9847 | O30: 1.0758 | P30: =O30-N30 -> 0.0911 | Q30: 0.977 | R30: 1.0243 | S30: =R30-Q30 -> 0.0473 | V30: AT2_43-63 | W30: P27 | X30: A35 | Y30: anaerobic | Z30: A35 x | AA30: 70 | AB30: Yes | AC30: 0.359 | AD30: 1.5465138 | AE30: =AC30/(1+AD30) -> 0.14097705 | AF30: =AE30*AD30 -> 0.21802295 | AG30: 140 | AH30: 0.38 | AI30: =AH30-((AG30/1000)/(AC30+AG30/1000))*AH30 -> 0.27338677 | AJ30: =AI30*1000 -> 273.38677 | AK30: =((AH30)-((AG30/1000)/(AE30+AF30+AG30/1000)*AH30))/(1+AD30) -> 0.10735727 | AL30: 0.9849 | AM30: 1.0765 | AN30: =AM30-AL30 -> 0.0916 | AO30: 0.979 | AP30: 1.0278 | AQ30: =AP30-AO30 -> 0.0488
A31: AP2_50-69 | B31: P8 | C31: A8 | D31: aerobic | E31: A8 | F31: 15 | G31: No | H31: 0.3518 | I31: =H31*1000 -> 351.8 | J31: ='3_Pre-incubation'!K19 -> 1.5682765 | K31: =H31/(1+J31) -> 0.13697902 | L31: =K31*J31 -> 0.21482098 | M31: 150 | N31: 0.9836 | O31: 1.0788 | P31: =O31-N31 -> 0.0952 | Q31: 0.9765 | R31: 1.0238 | S31: =R31-Q31 -> 0.0473 | V31: AT2_63-83 | W31: P28 | X31: A36 | Y31: anaerobic | Z31: A36 | AA31: 71 | AB31: No | AC31: 0.369 | AD31: 1.5312292 | AE31: =AC31/(1+AD31) -> 0.14577898 | AF31: =AE31*AD31 -> 0.22322102 | AG31: 148 | AH31: 0.3563 | AI31: =AH31-((AG31/1000)/(AC31+AG31/1000))*AH31 -> 0.25430309 | AJ31: =AI31*1000 -> 254.30309 | AK31: =((AH31)-((AG31/1000)/(AE31+AF31+AG31/1000)*AH31))/(1+AD31) -> 0.10046625 | AL31: 0.9801 | AM31: 1.0729 | AN31: =AM31-AL31 -> 0.0928 | AO31: 0.9794 | AP31: 1.0287 | AQ31: =AP31-AO31 -> 0.0493
A32: AP2_50-69 | B32: P8 | C32: A8 | D32: aerobic | E32: A8 x | F32: 16 | G32: Yes | H32: 0.3492 | I32: =H32*1000 -> 349.2 | J32: =J31 -> 1.5682765 | K32: =H32/(1+J32) -> 0.13596667 | L32: =K32*J32 -> 0.21323333 | M32: 150 | N32: 0.9862 | O32: 1.0794 | P32: =O32-N32 -> 0.0932 | Q32: 0.982 | R32: 1.0289 | S32: =R32-Q32 -> 0.0469 | V32: AT2_63-83 | W32: P28 | X32: A36 | Y32: anaerobic | Z32: A36 x | AA32: 72 | AB32: Yes | AC32: =0.373-0.0117 -> 0.3613 | AD32: 1.5312292 | AE32: =AC32/(1+AD32) -> 0.14273698 | AF32: =AE32*AD32 -> 0.21856302 | AG32: 140 | AH32: 0.375 | AI32: =AH32-((AG32/1000)/(AC32+AG32/1000))*AH32 -> 0.27027229 | AJ32: =AI32*1000 -> 270.27229 | AK32: =((AH32)-((AG32/1000)/(AE32+AF32+AG32/1000)*AH32))/(1+AD32) -> 0.10677512 | AL32: 0.9848 | AM32: 1.0776 | AN32: =AM32-AL32 -> 0.0928 | AO32: 0.9843 | AP32: 1.0312 | AQ32: =AP32-AO32 -> 0.0469
A33: AP2_80-100 | B33: P9 | C33: A9 | D33: aerobic | E33: A9 | F33: 17 | G33: No | H33: 0.3489 | I33: =H33*1000 -> 348.9 | J33: ='3_Pre-incubation'!K20 -> 1.5300947 | K33: =H33/(1+J33) -> 0.13789998 | L33: =K33*J33 -> 0.21100002 | M33: 150 | N33: 0.9777 | O33: 1.0712 | P33: =O33-N33 -> 0.0935 | Q33: 0.9797 | R33: 1.0267 | S33: =R33-Q33 -> 0.047 | V33: AT2_123-143 | W33: P29 | X33: A37 | Y33: anaerobic | Z33: A37 | AA33: 73 | AB33: No | AC33: 0.3614 | AD33: 1.5484277 | AE33: =AC33/(1+AD33) -> 0.14181293 | AF33: =AE33*AD33 -> 0.21958707 | AG33: 168 | AH33: 0.3559 | AI33: =AH33-((AG33/1000)/(AC33+AG33/1000))*AH33 -> 0.24295856 | AJ33: =AI33*1000 -> 242.95856 | AK33: =((AH33)-((AG33/1000)/(AE33+AF33+AG33/1000)*AH33))/(1+AD33) -> 0.09533665 | AL33: 0.9726 | AM33: 1.0682 | AN33: =AM33-AL33 -> 0.0956 | AO33: 0.9792 | AP33: 1.0272 | AQ33: =AP33-AO33 -> 0.048
A34: AP2_80-100 | B34: P9 | C34: A9 | D34: aerobic | E34: A9 x | F34: 18 | G34: Yes | H34: 0.3458 | I34: =H34*1000 -> 345.8 | J34: =J33 -> 1.5300947 | K34: =H34/(1+J34) -> 0.13667473 | L34: =K34*J34 -> 0.20912527 | M34: 150 | N34: 0.9807 | O34: 1.0758 | P34: =O34-N34 -> 0.0951 | Q34: 0.9761 | R34: 1.0231 | S34: =R34-Q34 -> 0.047 | V34: AT2_123-143 | W34: P29 | X34: A37 | Y34: anaerobic | Z34: A37 x | AA34: 74 | AB34: Yes | AC34: =0.3739-0.0094 -> 0.3645 | AD34: 1.5484277 | AE34: =AC34/(1+AD34) -> 0.14302937 | AF34: =AE34*AD34 -> 0.22147063 | AG34: 131 | AH34: 0.3906 | AI34: =AH34-((AG34/1000)/(AC34+AG34/1000))*AH34 -> 0.2873334 | AJ34: =AI34*1000 -> 287.3334 | AK34: =((AH34)-((AG34/1000)/(AE34+AF34+AG34/1000)*AH34))/(1+AD34) -> 0.11274929 | AL34: 0.9832 | AM34: 1.0788 | AN34: =AM34-AL34 -> 0.0956 | AO34: 0.9797 | AP34: 1.0283 | AQ34: =AP34-AO34 -> 0.0486
A35: AP2_100-120 | B35: P10 | C35: A10 | D35: aerobic | E35: A10 | F35: 19 | G35: No | H35: 0.3539 | I35: =H35*1000 -> 353.9 | J35: ='3_Pre-incubation'!K21 -> 1.4972165 | K35: =H35/(1+J35) -> 0.14171779 | L35: =K35*J35 -> 0.21218221 | M35: 150 | N35: 0.9736 | O35: 1.0672 | P35: =O35-N35 -> 0.0936 | Q35: 0.9824 | R35: 1.0293 | S35: =R35-Q35 -> 0.0469 | V35: AT2_143-163 | W35: P30 | X35: A38 | Y35: anaerobic | Z35: A38 | AA35: 75 | AB35: No | AC35: =0.3824-0.0207 -> 0.3617 | AD35: 1.5504667 | AE35: =AC35/(1+AD35) -> 0.14181718 | AF35: =AE35*AD35 -> 0.21988282 | AG35: 139 | AH35: 0.3842 | AI35: =AH35-((AG35/1000)/(AC35+AG35/1000))*AH35 -> 0.27754172 | AJ35: =AI35*1000 -> 277.54172 | AK35: =((AH35)-((AG35/1000)/(AE35+AF35+AG35/1000)*AH35))/(1+AD35) -> 0.10881997 | AL35: 0.9851 | AM35: 1.0806 | AN35: =AM35-AL35 -> 0.0955 | AO35: 0.9835 | AP35: 1.0317 | AQ35: =AP35-AO35 -> 0.0482
A36: AP2_100-120 | B36: P10 | C36: A10 | D36: aerobic | E36: A10 x | F36: 20 | G36: Yes | H36: 0.3495 | I36: =H36*1000 -> 349.5 | J36: =J35 -> 1.4972165 | K36: =H36/(1+J36) -> 0.13995583 | L36: =K36*J36 -> 0.20954417 | M36: 150 | N36: 0.9806 | O36: 1.0736 | P36: =O36-N36 -> 0.093 | Q36: 0.983 | R36: 1.0308 | S36: =R36-Q36 -> 0.0478 | V36: AT2_143-163 | W36: P30 | X36: A38 | Y36: anaerobic | Z36: A38 x | AA36: 76 | AB36: Yes | AC36: 0.3551 | AD36: 1.5504667 | AE36: =AC36/(1+AD36) -> 0.13922942 | AF36: =AE36*AD36 -> 0.21587058 | AG36: 141 | AH36: 0.3623 | AI36: =AH36-((AG36/1000)/(AC36+AG36/1000))*AH36 -> 0.25932822 | AJ36: =AI36*1000 -> 259.32822 | AK36: =((AH36)-((AG36/1000)/(AE36+AF36+AG36/1000)*AH36))/(1+AD36) -> 0.10167873 | AL36: 0.9818 | AM36: 1.0766 | AN36: =AM36-AL36 -> 0.0948 | AO36: 0.9822 | AP36: 1.0311 | AQ36: =AP36-AO36 -> 0.0489
A37: AP3_0-20 | B37: P11 | C37: A11 | D37: aerobic | E37: A11 | F37: 21 | G37: No | H37: 0.3481 | I37: =H37*1000 -> 348.1 | J37: ='3_Pre-incubation'!K22 -> 1.5136847 | K37: =H37/(1+J37) -> 0.13848196 | L37: =K37*J37 -> 0.20961804 | M37: 150 | N37: 0.981 | O37: 1.0749 | P37: =O37-N37 -> 0.0939 | Q37: 0.9811 | R37: 1.0279 | S37: =R37-Q37 -> 0.0468 | V37: AT3_0-40 | W37: P31 | X37: A39 | Y37: anaerobic | Z37: A39 | AA37: 77 | AB37: No | AC37: =0.3886-0.0272 -> 0.3614 | AD37: 2.519805 | AE37: =AC37/(1+AD37) -> 0.10267614 | AF37: =AE37*AD37 -> 0.25872386 | AG37: 153 | AH37: 0.3771 | AI37: =AH37-((AG37/1000)/(AC37+AG37/1000))*AH37 -> 0.26493767 | AJ37: =AI37*1000 -> 264.93767 | AK37: =((AH37)-((AG37/1000)/(AE37+AF37+AG37/1000)*AH37))/(1+AD37) -> 0.075270555 | AL37: 0.9778 | AM37: 1.0734 | AN37: =AM37-AL37 -> 0.0956 | AO37: 0.9855 | AP37: 1.0353 | AQ37: =AP37-AO37 -> 0.0498
A38: AP3_0-20 | B38: P11 | C38: A11 | D38: aerobic | E38: A11 x | F38: 22 | G38: Yes | H38: 0.3561 | I38: =H38*1000 -> 356.1 | J38: =J37 -> 1.5136847 | K38: =H38/(1+J38) -> 0.14166454 | L38: =K38*J38 -> 0.21443546 | M38: 150 | N38: 0.9781 | O38: 1.0767 | P38: =O38-N38 -> 0.0986 | Q38: 0.9822 | R38: 1.0293 | S38: =R38-Q38 -> 0.0471 | V38: AT3_0-40 | W38: P31 | X38: A39 | Y38: anaerobic | Z38: A39 x | AA38: 78 | AB38: Yes | AC38: =0.3746-0.0118 -> 0.3628 | AD38: 2.519805 | AE38: =AC38/(1+AD38) -> 0.10307389 | AF38: =AE38*AD38 -> 0.25972611 | AG38: 160 | AH38: 0.3666 | AI38: =AH38-((AG38/1000)/(AC38+AG38/1000))*AH38 -> 0.25440413 | AJ38: =AI38*1000 -> 254.40413 | AK38: =((AH38)-((AG38/1000)/(AE38+AF38+AG38/1000)*AH38))/(1+AD38) -> 0.072277905 | AL38: 0.9815 | AM38: 1.077 | AN38: =AM38-AL38 -> 0.0955 | AO38: 0.9806 | AP38: 1.0289 | AQ38: =AP38-AO38 -> 0.0483
A39: AP3_20-40 | B39: P12 | C39: A12 | D39: aerobic | E39: A12 | F39: 23 | G39: No | H39: 0.3523 | I39: =H39*1000 -> 352.3 | J39: ='3_Pre-incubation'!K23 -> 1.5060919 | K39: =H39/(1+J39) -> 0.14057745 | L39: =K39*J39 -> 0.21172255 | M39: 150 | N39: 0.9821 | O39: 1.0737 | P39: =O39-N39 -> 0.0916 | Q39: 0.9757 | R39: 1.0223 | S39: =R39-Q39 -> 0.0466 | V39: AT3_60-80 | W39: P32 | X39: A40 | Y39: anaerobic | Z39: A40 | AA39: 79 | AB39: No | AC39: =0.3874-0.0238 -> 0.3636 | AD39: 1.5365613 | AE39: =AC39/(1+AD39) -> 0.14334367 | AF39: =AE39*AD39 -> 0.22025633 | AG39: 151 | AH39: 0.3748 | AI39: =AH39-((AG39/1000)/(AC39+AG39/1000))*AH39 -> 0.26482176 | AJ39: =AI39*1000 -> 264.82176 | AK39: =((AH39)-((AG39/1000)/(AE39+AF39+AG39/1000)*AH39))/(1+AD39) -> 0.10440188 | AL39: 0.9864 | AM39: 1.0804 | AN39: =AM39-AL39 -> 0.094 | AO39: 0.9749 | AP39: 1.0234 | AQ39: =AP39-AO39 -> 0.0485
A40: AP3_20-40 | B40: P12 | C40: A12 | D40: aerobic | E40: A12 x | F40: 24 | G40: Yes | H40: 0.3502 | I40: =H40*1000 -> 350.2 | J40: =J39 -> 1.5060919 | K40: =H40/(1+J40) -> 0.13973949 | L40: =K40*J40 -> 0.21046051 | M40: 150 | N40: 0.9806 | O40: 1.0726 | P40: =O40-N40 -> 0.092 | Q40: 0.9834 | R40: 1.0297 | S40: =R40-Q40 -> 0.0463 | V40: AT3_60-80 | W40: P32 | X40: A40 | Y40: anaerobic | Z40: A40 x | AA40: 80 | AB40: Yes | AC40: =0.3748-0.0164 -> 0.3584 | AD40: 1.5365613 | AE40: =AC40/(1+AD40) -> 0.14129365 | AF40: =AE40*AD40 -> 0.21710635 | AG40: 143 | AH40: 0.3968 | AI40: =AH40-((AG40/1000)/(AC40+AG40/1000))*AH40 -> 0.28363207 | AJ40: =AI40*1000 -> 283.63207 | AK40: =((AH40)-((AG40/1000)/(AE40+AF40+AG40/1000)*AH40))/(1+AD40) -> 0.11181755 | AL40: 0.9814 | AM40: 1.0759 | AN40: =AM40-AL40 -> 0.0945 | AO40: 0.9747 | AP40: 1.0228 | AQ40: =AP40-AO40 -> 0.0481
A41: AP3_50-69 | B41: P13 | C41: A13 | D41: aerobic | E41: A13 | F41: 25 | G41: No | H41: 0.3536 | I41: =H41*1000 -> 353.6 | J41: ='3_Pre-incubation'!K24 -> 1.5224654 | K41: =H41/(1+J41) -> 0.14018032 | L41: =K41*J41 -> 0.21341968 | M41: 150 | N41: 0.9812 | O41: 1.0747 | P41: =O41-N41 -> 0.0935 | Q41: 0.9833 | R41: 1.0289 | S41: =R41-Q41 -> 0.0456 | V41: AT3_80-100 | W41: P33 | X41: A41 | Y41: anaerobic | Z41: A41 | AA41: 81 | AB41: No | AC41: =0.3839-0.0174 -> 0.3665 | AD41: 1.523754 | AE41: =AC41/(1+AD41) -> 0.14522017 | AF41: =AE41*AD41 -> 0.22127983 | AG41: 165 | AH41: 0.4009 | AI41: =AH41-((AG41/1000)/(AC41+AG41/1000))*AH41 -> 0.27644374 | AJ41: =AI41*1000 -> 276.44374 | AK41: =((AH41)-((AG41/1000)/(AE41+AF41+AG41/1000)*AH41))/(1+AD41) -> 0.10953672 | AL41: 0.9802 | AM41: 1.0751 | AN41: =AM41-AL41 -> 0.0949 | AO41: 0.9828 | AP41: 1.0306 | AQ41: =AP41-AO41 -> 0.0478
...

Sheet 5_Flushing
A1: Flushing
A2: Flushing of aerobic samples with synthetic air for ca. 15 min, creating overpressure for ca. 3 min
A3: Flushing of anaerobic samples with N2 for 20 min
A4: Aerobic samples: 27.11.24
A5: Anaerobic samples: 09.12.24
A8: Sample | B8: Beginning | C8: End | D8: Overpressure
A9: A1 | B9: 45623.351 | C9: 45623.36 | D9: 45623.363
A10: A2 | B10: 45623.509 | C10: 45623.517 | D10: 45623.519
A11: A3 | B11: 45623.351 | C11: 45623.36 | D11: 45623.363
A12: A4 | B12: 45623.351 | C12: 45623.36 | D12: 45623.363
A13: A5 | B13: 45623.351 | C13: 45623.36 | D13: 45623.363
A14: A6 | B14: 45623.351 | C14: 45623.36 | D14: 45623.363
A15: A7 | B15: 45623.351 | C15: 45623.36 | D15: 45623.363
A16: A8 | B16: 45623.351 | C16: 45623.36 | D16: 45623.363
A17: A9 | B17: 45623.351 | C17: 45623.36 | D17: 45623.363
A18: A10 | B18: 45623.351 | C18: 45623.36 | D18: 45623.363
A19: A11 | B19: 45623.365 | C19: 45623.374 | D19: 45623.376
A20: A12 | B20: 45623.365 | C20: 45623.374 | D20: 45623.376
... A64: A56 | B64: 45635.579 | C64: 45635.593 | D64: 45635.596

Sheet 6_GC measurements aerobic
A1: CO2 measurements aerobic samples
A2: 27.11.2024-29.11.2024
L5: Standards [ppm CO2] | M5: time
A6: t0 | L6: 895 | M6: 0.40277778 | N6: 0.40416667 | O6: 0.45 | P6: 0.52291667
A7: Sample | B7: Time | C7: t0 | D7: Overpressure [hPa] | E7: Area CO2 | F7: CO2 [ppm] | L7: 3000 | M7: 0.40555556 | N7: 0.40972222 | O7: 0.47569444 | P7: 0.52847222
A8: A1 | B8: 45623.426 | C8: 0 | D8: 798 | E8: 118.8355 | F8: =E8/$L$18 -> 115.73631 | L8: 7981 | M8: 0.42013889 | N8: 0.42152778 | O8: 0.42361111 | P8: 0.49930556
A9: A2 | B9: 45623.531 | C9: 0 | D9: 715 | E9: 17.535 | F9: =E9/$L$18 -> 17.077693
A10: A3 | B10: 45623.429 | C10: 0 | D10: 697 | E10: 175.366 | F10: =E10/$L$18 -> 170.79251
A11: A4 | B11: 45623.431 | C11: 0 | D11: 814 | E11: 631.396 | F11: =E11/$L$18 -> 614.92938 | K11: CO2
A12: A5 | B12: 45623.433 | C12: 0 | D12: 818 | E12: 1114.711 | F12: =E12/$L$18 -> 1085.6397 | K12: Standards [ppm CO2] | L12: Area mean | M12: Area1 | N12: Area2 | O12: Area3 | P12: Area4 | Q12: Area5
A13: A6 | B13: 45623.435 | C13: 0 | D13: 823 | E13: 156.921 | F13: =E13/$L$18 -> 152.82855 | K13: 0 | L13: 0
A14: A7 | B14: 45623.44 | C14: 0 | D14: 807 | E14: 45.2185 | F14: =E14/$L$18 -> 44.039215 | K14: 895 | L14: =AVERAGE(M14:Q14) -> 826.88275 | M14: 827.294 | N14: 830.822 | O14: 822.429 | P14: 826.986
A15: A8 | B15: 45623.443 | C15: 0 | D15: 810 | E15: 106.0765 | F15: =E15/$L$18 -> 103.31006 | K15: 3000 | L15: =AVERAGE(M15:Q15) -> 3084.2856 | M15: 3090.468 | N15: 3165.968 | O15: 3098.187 | P15: 2982.5195
A16: A9 | B16: 45623.445 | C16: 0 | D16: 821 | E16: 207.176 | F16: =E16/$L$18 -> 201.77291 | K16: 7981 | L16: =AVERAGE(M16:Q16) -> 8203.5567 | M16: 8327.764 | N16: 8096.529 | O16: 8156.062 | P16: 8233.872
A17: A10 | B17: 45623.448 | C17: 0 | D17: 815 | E17: 166.44 | F17: =E17/$L$18 -> 162.0993
A18: A11 | B18: 45623.452 | C18: 0 | D18: 715 | E18: 155.84 | F18: =E18/$L$18 -> 151.77574 | K18: Faktor_Area_CO2 | L18: {=LINEST(L13:L16,K13:K16,FALSE,FALSE)} -> 1.0267781 | M18: 0
A19: A12 | B19: 45623.454 | C19: 0 | D19: 845 | E19: 67.5345 | F19: =E19/$L$18 -> 65.773221
A20: A13 | B20: 45623.457 | C20: 0 | D20: 783 | E20: 121.1555 | F20: =E20/$L$18 -> 117.9958
A21: A14 | B21: 45623.459 | C21: 0 | D21: 828 | E21: 101.8385 | F21: =E21/$L$18 -> 99.182583
A22: A15 | B22: 45623.461 | C22: 0 | D22: 719 | E22: 151.349 | F22: =E22/$L$18 -> 147.40186
A23: A16 | B23: 45623.464 | C23: 0 | D23: 844 | E23: 267.862 | F23: =E23/$L$18 -> 260.87624
A24: A17 | B24: 45623.466 | C24: 0 | D24: 827 | E24: 58.591 | F24: =E24/$L$18 -> 57.062965
A25: A18 | B25: 45623.469 | C25: 0 | D25: 748 | E25: 97.83 | F25: =E25/$L$18 -> 95.278623 | K25: T_raum [°C] | L25: 22
A26: A19 | B26: 45623.471 | C26: 0 | D26: 840 | E26: 101.595 | F26: =E26/$L$18 -> 98.945433 | K26: P_raum [hPa] | L26: 981.6
A27: A20 | B27: 45623.432 | C27: 0 | D27: 810 | E27: 161.947 | F27: =E27/$L$18 -> 157.72347 | K27: rel_Hum [%] | L27: 40.7
A28: A21 | B28: 45623.478 | C28: 0 | D28: 831 | E28: 158.761 | F28: =E28/$L$18 -> 154.62056
A29: A22 | B29: 45623.483 | C29: 0 | D29: 843 | E29: 128.685 | F29: =E29/$L$18 -> 125.32893
A30: A23 | B30: 45623.485 | C30: 0 | D30: 820 | E30: 109.341 | F30: =E30/$L$18 -> 106.48942
A31: A24 | B31: 45623.487 | C31: 0 | D31: 790 | E31: 189.5905 | F31: =E31/$L$18 -> 184.64604
A32: A25 | B32: 45623.49 | C32: 0 | D32: 851 | E32: 121.053 | F32: =E32/$L$18 -> 117.89597
A33: A26 | B33: 45623.492 | C33: 0 | D33: 855 | E33: 128.627 | F33: =E33/$L$18 -> 125.27245
A34: A27 | B34: 45623.494 | C34: 0 | D34: 832 | E34: 123.085 | F34: =E34/$L$18 -> 119.87498
A35: A28 | B35: 45623.497 | C35: 0 | D35: 792 | E35: 103.198 | F35: =E35/$L$18 -> 100.50663
A43: t1
A44: Sample | B44: Time | C44: t1 | D44: Overpressure [hPa] | E44: Area CO2 | F44: CO2 [ppm] | G44: Differenz vorherige Messung | L44: Standards [ppm CO2] | M44: time
A45: A1 | B45: 45624.363 | C45: =(B45-B8)*24 -> 22.483333 | E45: 1810.2385 | F45: =E45/$L$57 -> 1678.8312 | G45: =E45-E8 -> 1691.403 | L45: 895 | M45: 0.34791667 | N45: 0.35 | O45: 0.39166667
A46: A2 | B46: 45624.444 | C46: =(B46-B9)*24 -> 21.916667 | E46: 920.465 | F46: =E46/$L$57 -> 853.64737 | G46: =E46-E9 -> 902.93 | L46: 3000 | M46: 0.35208333 | N46: 0.35486111 | O46: 0.41875 | P46: 0.42361111
A47: A3 | B47: 45624.365 | C47: =(B47-B10)*24 -> 22.45 | E47: 2607.8075 | F47: =E47/$L$57 -> 2418.5037 | G47: =E47-E10 -> 2432.4415 | L47: 7981 | M47: 0.35694444 | N47: 0.35972222 | O47: 0.44722222 | P47: 0.44930556
A48: A4 | B48: 45624.367 | C48: =(B48-B11)*24 -> 22.466667 | E48: 8233.33 | F48: =E48/$L$57 -> 7635.6629 | G48: =E48-E11 -> 7601.934
A49: A5 | B49: 45624.369 | C49: =(B49-B12)*24 -> 22.466667 | E49: 13673.256 | F49: =E49/$L$57 -> 12680.698 | G49: =E49-E12 -> 12558.545
...

Sheet 7_GC measurements anaerobic
A1: CO2 measurements anaerobic samples | AC1: CO2 | BF1: CH4
A2: 9.12.2024 - 16.12.2024
O5: Standards [ppm CO2] | P5: time
A6: t0 | O6: 895 | P6: 0.58194444 | Q6: 0.58472222 | R6: 0.64513889
A7: Sample | B7: Time | C7: t0 | D7: Overpressure [hPa] | E7: Area CO2 | F7: CO2 [ppm] | G7: Area CH4 | H7: CH4 [ppm] | O7: 3000 | P7: 0.60208333 | Q7: 0.60555556 | R7: 0.68055556
A8: A29 | B8: 45635.617 | C8: 0 | D8: 771 | E8: 41.423 | F8: =E8/$O$18 -> 39.36424 | G8: 14.746 | H8: =G8/$O$34 -> 2.0053113 | O8: 7981 | P8: 0.60902778 | Q8: 0.6125 | R8: 0.71111111
A9: A30 | B9: 45635.62 | C9: 0 | D9: 795 | E9: 21.7935 | F9: =E9/$O$18 -> 20.710344 | G9: 1.289 | H9: =G9/$O$34 -> 0.17529135
A10: A31 | B10: 45635.624 | C10: 0 | D10: 788 | E10: 47.671 | F10: =E10/$O$18 -> 45.301709 | G10: 0.6595 | H10: =G10/$O$34 -> 0.089685528
A11: A32 | B11: 45635.627 | C11: 0 | D11: 809 | E11: 45.837 | F11: =E11/$O$18 -> 43.558861 | G11: 0.533 | H11: =G11/$O$34 -> 0.072482769 | N11: CO2
A12: A33 | B12: 45635.63 | C12: 0 | D12: 710 | E12: 42.532 | F12: =E12/$O$18 -> 40.418122 | G12: 0 | H12: =G12/$O$34 -> 0 | N12: Standards [ppm CO2] | O12: Area mean | P12: Area1 | Q12: Area2 | R12: Area3 | S12: Area4 | T12: Area5
A13: A34 | B13: 45635.708 | C13: 0 | D13: 854 | E13: 26.963 | F13: =E13/$O$18 -> 25.622915 | G13: 0 | H13: =G13/$O$34 -> 0 | N13: 0 | O13: 0
A14: A35 | B14: 45635.633 | C14: 0 | D14: 762 | E14: 18.401 | F14: =E14/$O$18 -> 17.486454 | G14: 0 | H14: =G14/$O$34 -> 0 | N14: 895 | O14: =AVERAGE(P14:T14) -> 823.848 | P14: 835.378 | Q14: 825.159 | R14: 811.007
A15: A36 | B15: 45635.636 | C15: 0 | D15: 765 | E15: 21.015 | F15: =E15/$O$18 -> 19.970536 | G15: 0.652 | H15: =G15/$O$34 -> 0.088665602 | N15: 3000 | O15: =AVERAGE(P15:T15) -> 3064.5768 | P15: 2970.821 | Q15: 3139.707 | R15: 3083.2025
A16: A37 | B16: 45635.64 | C16: 0 | D16: 766 | E16: 22.67 | F16: =E16/$O$18 -> 21.543281 | G16: 0 | H16: =G16/$O$34 -> 0 | N16: 7981 | O16: =AVERAGE(P16:T16) -> 8446.3405 | P16: 8423.0315 | Q16: 8515.152 | R16: 8400.838
A17: A38 | B17: 45635.642 | C17: 0 | D17: 763 | E17: 64.698 | F17: =E17/$O$18 -> 61.482452 | G17: 0 | H17: =G17/$O$34 -> 0
A18: A39 | B18: 45635.649 | C18: 0 | D18: 806 | E18: 24.1145 | F18: =E18/$O$18 -> 22.915988 | G18: 0 | H18: =G18/$O$34 -> 0 | N18: Faktor_Area_CO2 | O18: {=LINEST(O13:O16,N13:N16,FALSE,FALSE)} -> 1.0523003 | P18: 0
A19: A40 | B19: 45635.651 | C19: 0 | D19: 813 | E19: 30.4915 | F19: =E19/$O$18 -> 28.976045 | G19: 0 | H19: =G19/$O$34 -> 0
A20: A41 | B20: 45635.656 | C20: 0 | D20: 786 | E20: 21.5375 | F20: =E20/$O$18 -> 20.467067 | G20: 0 | H20: =G20/$O$34 -> 0
A21: A42 | B21: 45635.66 | C21: 0 | D21: 819 | E21: 29.4045 | F21: =E21/$O$18 -> 27.94307 | G21: 0 | H21: =G21/$O$34 -> 0 | O21: Standards [ppm CH4] | P21: time
A22: A43 | B22: 45635.662 | C22: 0 | D22: 800 | E22: 34.909 | F22: =E22/$O$18 -> 33.173992 | G22: 0 | H22: =G22/$O$34 -> 0 | O22: 2 | P22: 0.5875 | Q22: 0.59861111 | R22: 0.64513889
